<?xml version="1.0" ?>
<!-- =================================================================================== -->
<!-- |    This document was autogenerated by xacro from irb120_workcell.xacro          | -->
<!-- |    EDITING THIS FILE BY HAND IS NOT RECOMMENDED                                 | -->
<!-- =================================================================================== -->
<robot name="irb120_workcell" xmlns:xacro="http://ros.org/wiki/xacro">
  <link name="world_frame"/>
  <!-- Defining the robotic enclosure-->
  <link name="enclosure">
    <visual>
      <origin rpy="1.57079633 0 3.14159266" xyz="1 -0.625 0"/>
      <geometry>
        <mesh filename="package://irb120_workcell_config/meshes/enclosure.STL" scale="0.001 0.001 0.001"/>
      </geometry>
      <material name="glass">
        <color rgba="1 1 1 0.3"/>
      </material>
    </visual>
  </link>
  <joint name="enclosure_to_world" type="fixed">
    <parent link="world_frame"/>
    <child link="enclosure"/>
    <origin rpy="0 0 0" xyz="0.45 0 0"/>
  </joint>
  <!-- Defining the robot and mounting it in the enclosure -->
  <link name="base_link">
    <visual>
      <origin rpy="1.57079633 0 0" xyz="0 0 0"/>
      <geometry>
        <mesh filename="package://abb_irb120_support/meshes/irb120/visual/base_link.stl" scale="0.0254 0.0254 0.0254"/>
      </geometry>
      <material name="abb_orange">
        <color rgba="1 0.43 0 1"/>
      </material>
    </visual>
    <collision>
      <geometry>
        <mesh filename="package://abb_irb120_support/meshes/irb120/collision/base_link.stl" scale="0.0254 0.0254 0.0254"/>
      </geometry>
      <material name="yellow">
        <color rgba="0 1 1 1"/>
      </material>
    </collision>
  </link>
  <link name="link_1">
    <visual>
      <origin rpy="1.57079633 0 0" xyz="0 0 -0.17649952"/>
      <geometry>
        <mesh filename="package://abb_irb120_support/meshes/irb120/visual/link_1.stl" scale="0.0254 0.0254 0.0254"/>
      </geometry>
      <material name="abb_orange"/>
    </visual>
    <collision>
      <origin rpy="1.57079633 0 0" xyz="0 0 -0.17649952"/>
      <geometry>
        <mesh filename="package://abb_irb120_support/meshes/irb120/collision/link_1.stl" scale="0.0254 0.0254 0.0254"/>
      </geometry>
      <material name="yellow"/>
    </collision>
  </link>
  <link name="link_2">
    <visual>
      <origin rpy="1.57079633 0 0" xyz="1.54358428872e-06 -0.115499748015 0.269999754796"/>
      <geometry>
        <mesh filename="package://abb_irb120_support/meshes/irb120/visual/link_2.stl" scale="0.0254 0.0254 0.0254"/>
      </geometry>
      <material name="abb_orange"/>
    </visual>
    <collision>
      <origin rpy="1.57079633 0 0" xyz="1.54358428872e-06 -0.115499748015 0.269999754796"/>
      <geometry>
        <mesh filename="package://abb_irb120_support/meshes/irb120/collision/link_2.stl" scale="0.0254 0.0254 0.0254"/>
      </geometry>
      <material name="yellow"/>
    </collision>
  </link>
  <link name="link_3">
    <visual>
      <origin rpy="1.57079633 0 0" xyz="0.071952848745 -0.0589997805382 -0.0661526901756"/>
      <geometry>
        <mesh filename="package://abb_irb120_support/meshes/irb120/visual/link_3.stl" scale="0.0254 0.0254 0.0254"/>
      </geometry>
      <material name="abb_orange"/>
    </visual>
    <collision>
      <origin rpy="1.57079633 0 0" xyz="0.071952848745 -0.0589997805382 -0.0661526901756"/>
      <geometry>
        <mesh filename="package://abb_irb120_support/meshes/irb120/collision/link_3.stl" scale="0.0254 0.0254 0.0254"/>
      </geometry>
      <material name="yellow"/>
    </collision>
  </link>
  <link name="link_4">
    <visual>
      <origin rpy="1.57079633 0 0" xyz="500.302187012 0.000313229561613 0.00151561224702"/>
      <geometry>
        <mesh filename="package://abb_irb120_support/meshes/irb120/visual/link_4.stl" scale="0.0254 0.0254 0.0254"/>
      </geometry>
      <material name="abb_orange"/>
    </visual>
    <collision>
      <origin rpy="1.57079633 0 0" xyz="500.302187012 0.000313229561613 0.00151561224702"/>
      <geometry>
        <mesh filename="package://abb_irb120_support/meshes/irb120/collision/link_4.stl" scale="0.0254 0.0254 0.0254"/>
      </geometry>
      <material name="yellow"/>
    </collision>
  </link>
  <link name="link_5">
    <visual>
      <origin rpy="1.57079633 0 0" xyz="-0.301998488439 0.0619993114233 -0.629998750685"/>
      <geometry>
        <mesh filename="package://abb_irb120_support/meshes/irb120/visual/link_5.stl" scale="0.0254 0.0254 0.0254"/>
      </geometry>
      <material name="abb_orange"/>
    </visual>
    <collision>
      <origin rpy="1.57079633 0 0" xyz="-0.301998488439 0.0619993114233 -0.629998750685"/>
      <geometry>
        <mesh filename="package://abb_irb120_support/meshes/irb120/collision/link_5.stl" scale="0.0254 0.0254 0.0254"/>
      </geometry>
      <material name="yellow"/>
    </collision>
  </link>
  <link name="link_6">
    <visual>
      <origin rpy="1.57079633 0 0" xyz="-2.74896335695e-07 0.0130000906507 -8.57788299224e-07"/>
      <geometry>
        <mesh filename="package://abb_irb120_support/meshes/irb120/visual/link_6.stl" scale="0.0254 0.0254 0.0254"/>
      </geometry>
      <material name="abb_orange"/>
    </visual>
    <collision>
      <origin rpy="1.57079633 0 0" xyz="-2.74896335695e-07 0.0130000906507 -8.57788299224e-07"/>
      <geometry>
        <mesh filename="package://abb_irb120_support/meshes/irb120/collision/link_6.stl" scale="0.0254 0.0254 0.0254"/>
      </geometry>
      <material name="yellow"/>
    </collision>
  </link>
  <link name="tool0"/>
  <joint name="joint_1" type="revolute">
    <origin rpy="-3.14159265359 -3.14159265359 3.14159265359" xyz="0 8.0162399451E-005 0.17649952"/>
    <parent link="base_link"/>
    <child link="link_1"/>
    <axis xyz="0 0 1"/>
    <limit effort="300" lower="-2.88" upper="2.88" velocity="4.36"/>
    <calibration falling="0" rising="0"/>
    <dynamics damping="0" friction="0"/>
  </joint>
  <joint name="joint_2" type="revolute">
    <origin rpy="3.14159265359 -3.14159265359 0" xyz="0 -0.0574996276953 0.1134999"/>
    <parent link="link_1"/>
    <child link="link_2"/>
    <axis xyz="0 -1 0"/>
    <limit effort="0" lower="-1.9199" upper="1.9199" velocity="4.36"/>
    <calibration falling="0" rising="0"/>
    <dynamics damping="0" friction="0"/>
  </joint>
  <joint name="joint_3" type="revolute">
    <origin rpy="3.14159265359 -3.14159265359 0" xyz="0 -0.108 0.270000153642"/>
    <parent link="link_2"/>
    <child link="link_3"/>
    <axis xyz="0 1 0"/>
    <limit effort="0" lower="-1.9199" upper="1.2217" velocity="4.36"/>
    <calibration falling="0" rising="0"/>
    <dynamics damping="0" friction="0"/>
  </joint>
  <joint name="joint_4" type="revolute">
    <origin rpy="0 0 0" xyz="-500.000188071 -0.060593734446 0.0701403024607"/>
    <parent link="link_3"/>
    <child link="link_4"/>
    <axis xyz="1 0 0"/>
    <limit effort="0" lower="-2.7925" upper="2.7925" velocity="5.585"/>
    <calibration falling="0" rising="0"/>
    <dynamics damping="0" friction="0"/>
  </joint>
  <joint name="joint_5" type="revolute">
    <origin rpy="0 0 0" xyz="500.302186066 -0.0616850168905 0.00151566707848"/>
    <parent link="link_4"/>
    <child link="link_5"/>
    <axis xyz="0 1 0"/>
    <limit effort="0" lower="-2.0944" upper="2.0944" velocity="5.585"/>
    <calibration falling="0" rising="0"/>
    <dynamics damping="0" friction="0"/>
  </joint>
  <joint name="joint_6" type="revolute">
    <origin rpy="-1.5707961734 1.57079621992 0" xyz="0.072000865279 0.0620001796247 0"/>
    <parent link="link_5"/>
    <child link="link_6"/>
    <axis xyz="0 -1 0"/>
    <limit effort="0" lower="-6.9813" upper="6.9813" velocity="7.33"/>
    <calibration falling="0" rising="0"/>
    <dynamics damping="0" friction="0"/>
  </joint>
  <joint name="joint_6-tool0" type="fixed">
    <parent link="link_6"/>
    <child link="tool0"/>
    <origin rpy="0 0 0" xyz="0 0 0"/>
  </joint>
  <joint name="robot_to_enclosure" type="fixed">
    <parent link="world_frame"/>
    <child link="base_link"/>
    <origin rpy="0 0 0" xyz="0 0 0.025"/>
  </joint>
  <!-- Defining the pegboard and placing it in front of the robot-->
  <link name="pegboard">
    <visual>
      <origin rpy="1.57079633 0 -1.57079633" xyz="0.225 0.15 0.01"/>
      <geometry>
        <mesh filename="package://irb120_workcell_config/meshes/pegboard.STL" scale="0.001 0.001 0.001"/>
      </geometry>
      <material name="blue">
        <color rgba="0.3 0.3 1 1"/>
      </material>
    </visual>
  </link>
  <joint name="pegboard_to_floor" type="fixed">
    <parent link="enclosure"/>
    <child link="pegboard"/>
    <origin rpy="0 0 0" xyz="-0.13 0 -0.005"/>
  </joint>
  <!-- Defining the robotic manipulator and mounting it to the robot -->
  <!--   <xacro:s-model_mesh prefix="g_"/>
  <joint name="gripper_to_robot" type="fixed">
    <parent link="tool0"/>
    <child link="g_palm"/>
    <origin xyz="0 -0.161 0" rpy="1.570 -2.356 0"/>
  </joint>
 -->
</robot>

