<?xml version="1.0" ?>
<!-- =================================================================================== -->
<!-- |    This document was autogenerated by xacro from irb120_robotiq.xacro           | -->
<!-- |    EDITING THIS FILE BY HAND IS NOT RECOMMENDED                                 | -->
<!-- =================================================================================== -->
<robot name="abb_irb120_robotiq" xmlns:xacro="http://www.ros.org/wiki/xacro">
  <link name="robot_base_link">
    <inertial>
      <mass value="6.215"/>
      <origin rpy="0 0 0" xyz="-0.04204 8.01E-05 0.07964"/>
      <inertia ixx="0.0247272" ixy="-8.0784E-05" ixz="0.00130902" iyy="0.0491285" iyz="-8.0419E-06" izz="0.0472376"/>
    </inertial>
    <visual>
      <origin rpy="0 0 0" xyz="0 0 0"/>
      <geometry>
        <mesh filename="package://abb_irb120_support/meshes/irb120/visual/base_link.stl"/>
      </geometry>
      <material name="abb_orange">
        <color rgba="1 0.43 0 1"/>
      </material>
    </visual>
    <collision>
      <origin rpy="0 0 0" xyz="0 0 0"/>
      <geometry>
        <mesh filename="package://abb_irb120_support/meshes/irb120/collision/base_link.stl"/>
      </geometry>
      <material name="yellow">
        <color rgba="0 1 1 1"/>
      </material>
    </collision>
  </link>
  <link name="robot_link_1">
    <inertial>
      <mass value="3.067"/>
      <origin rpy="0 0 0" xyz="9.77E-05 -0.00012 0.23841"/>
      <inertia ixx="0.0142175" ixy="-1.28579E-05" ixz="-2.31364E-05" iyy="0.0144041" iyz="1.93404E-05" izz="0.0104533"/>
    </inertial>
    <visual>
      <origin rpy="0 0 0" xyz="0 0 0"/>
      <geometry>
        <mesh filename="package://abb_irb120_support/meshes/irb120/visual/link_1.stl"/>
      </geometry>
      <material name="abb_orange"/>
    </visual>
    <collision>
      <origin rpy="0 0 0" xyz="0 0 0"/>
      <geometry>
        <mesh filename="package://abb_irb120_support/meshes/irb120/collision/link_1.stl"/>
      </geometry>
      <material name="yellow"/>
    </collision>
  </link>
  <link name="robot_link_2">
    <inertial>
      <mass value="3.909"/>
      <origin rpy="0 0 0" xyz="0.00078 -0.00212 0.10124"/>
      <inertia ixx="0.0603111" ixy="9.83431E-06" ixz="5.72407E-05" iyy="0.041569" iyz="-0.00050497" izz="0.0259548"/>
    </inertial>
    <visual>
      <origin rpy="0 0 0" xyz="0 0 0"/>
      <geometry>
        <mesh filename="package://abb_irb120_support/meshes/irb120/visual/link_2.stl"/>
      </geometry>
      <material name="abb_orange"/>
    </visual>
    <collision>
      <origin rpy="0 0 0" xyz="0 0 0"/>
      <geometry>
        <mesh filename="package://abb_irb120_support/meshes/irb120/collision/link_2.stl"/>
      </geometry>
      <material name="yellow"/>
    </collision>
  </link>
  <link name="robot_link_3">
    <inertial>
      <mass value="2.944"/>
      <origin rpy="0 0 0" xyz="0.02281 0.00106 0.05791"/>
      <inertia ixx="0.00835606" ixy="-8.01545E-05" ixz="0.00142884" iyy="0.016713" iyz="-0.000182227" izz="0.0126984"/>
    </inertial>
    <visual>
      <origin rpy="0 0 0" xyz="0 0 0"/>
      <geometry>
        <mesh filename="package://abb_irb120_support/meshes/irb120/visual/link_3.stl"/>
      </geometry>
      <material name="abb_orange"/>
    </visual>
    <collision>
      <origin rpy="0 0 0" xyz="0 0 0"/>
      <geometry>
        <mesh filename="package://abb_irb120_support/meshes/irb120/collision/link_3.stl"/>
      </geometry>
      <material name="yellow"/>
    </collision>
  </link>
  <link name="robot_link_4">
    <inertial>
      <mass value="1.328"/>
      <origin rpy="0 0 0" xyz="0.2247 0.00015 0.00041"/>
      <inertia ixx="0.00284661" ixy="-2.12765E-05" ixz="-1.6435E-05" iyy="0.00401346" iyz="1.31336E-05" izz="0.0052535"/>
    </inertial>
    <visual>
      <origin rpy="0 0 0" xyz="0 0 0"/>
      <geometry>
        <mesh filename="package://abb_irb120_support/meshes/irb120/visual/link_4.stl"/>
      </geometry>
      <material name="abb_orange"/>
    </visual>
    <collision>
      <origin rpy="0 0 0" xyz="0 0 0"/>
      <geometry>
        <mesh filename="package://abb_irb120_support/meshes/irb120/collision/link_4.stl"/>
      </geometry>
      <material name="yellow"/>
    </collision>
  </link>
  <link name="robot_link_5">
    <inertial>
      <mass value="0.546"/>
      <origin rpy="0 0 0" xyz="-0.00109 3.68E-05 6.22E-05"/>
      <inertia ixx="0.000404891" ixy="1.61943E-06" ixz="8.46805E-07" iyy="0.000892825" iyz="-1.51792E-08" izz="0.000815468"/>
    </inertial>
    <visual>
      <origin rpy="0 0 0" xyz="0 0 0"/>
      <geometry>
        <mesh filename="package://abb_irb120_support/meshes/irb120/visual/link_5.stl"/>
      </geometry>
      <material name="abb_orange"/>
    </visual>
    <collision>
      <origin rpy="0 0 0" xyz="0 0 0"/>
      <geometry>
        <mesh filename="package://abb_irb120_support/meshes/irb120/collision/link_5.stl"/>
      </geometry>
      <material name="yellow"/>
    </collision>
  </link>
  <link name="robot_link_6">
    <inertial>
      <mass value="0.137"/>
      <origin rpy="0 0 0" xyz="-0.00706 -0.00017 -1.32E-06"/>
      <inertia ixx="0.001" ixy="0" ixz="0" iyy="0.001" iyz="0" izz="0.001"/>
    </inertial>
    <visual>
      <origin rpy="0 0 0" xyz="0 0 0"/>
      <geometry>
        <mesh filename="package://abb_irb120_support/meshes/irb120/visual/link_6.stl"/>
      </geometry>
      <material name="black">
        <color rgba="0 0 0 1"/>
      </material>
    </visual>
    <collision>
      <origin rpy="0 0 0" xyz="0 0 0"/>
      <geometry>
        <mesh filename="package://abb_irb120_support/meshes/irb120/collision/link_6.stl"/>
      </geometry>
      <material name="yellow"/>
    </collision>
  </link>
  <link name="robot_tool0"/>
  <joint name="robot_joint_1" type="revolute">
    <origin rpy="0 0 0" xyz="0 0 0"/>
    <parent link="robot_base_link"/>
    <child link="robot_link_1"/>
    <limit effort="100" lower="-2.87979" upper="2.87979" velocity="4.36332"/>
    <axis xyz="0 0 1"/>
    <dynamics damping="0.0" friction="0.0"/>
  </joint>
  <joint name="robot_joint_2" type="revolute">
    <origin rpy="0 0 0" xyz="0 0 0.29"/>
    <parent link="robot_link_1"/>
    <child link="robot_link_2"/>
    <limit effort="100" lower="-1.91986" upper="1.91986" velocity="4.36332"/>
    <axis xyz="0 1 0"/>
    <dynamics damping="0.0" friction="0.0"/>
  </joint>
  <joint name="robot_joint_3" type="revolute">
    <origin rpy="0 0 0" xyz="0 0 0.27"/>
    <parent link="robot_link_2"/>
    <child link="robot_link_3"/>
    <limit effort="100" lower="-1.91986" upper="1.22173" velocity="4.36332"/>
    <axis xyz="0 1 0"/>
    <dynamics damping="0.0" friction="0.0"/>
  </joint>
  <joint name="robot_joint_4" type="revolute">
    <origin rpy="0 0 0" xyz="0 0 0.07"/>
    <parent link="robot_link_3"/>
    <child link="robot_link_4"/>
    <limit effort="30" lower="-2.79253" upper="2.79253" velocity="5.58505"/>
    <axis xyz="1 0 0"/>
    <dynamics damping="0.0" friction="0.0"/>
  </joint>
  <joint name="robot_joint_5" type="revolute">
    <origin rpy="0 0 0" xyz="0.302 0 0"/>
    <parent link="robot_link_4"/>
    <child link="robot_link_5"/>
    <limit effort="30" lower="-2.094395" upper="2.094395" velocity="5.58505"/>
    <axis xyz="0 1 0"/>
    <dynamics damping="0.0" friction="0.0"/>
  </joint>
  <joint name="robot_joint_6" type="revolute">
    <origin rpy="0 0 0" xyz="0.072 0 0"/>
    <parent link="robot_link_5"/>
    <child link="robot_link_6"/>
    <limit effort="30" lower="-6.98132" upper="6.98132" velocity="7.33038"/>
    <axis xyz="1 0 0"/>
    <dynamics damping="0.0" friction="0.0"/>
  </joint>
  <joint name="robot_joint6-tool0" type="fixed">
    <parent link="robot_link_6"/>
    <child link="robot_tool0"/>
    <origin rpy="0 0 0" xyz="0 0 0"/>
  </joint>
  <link name="robot_base"/>
  <joint name="robot_base_link-base" type="fixed">
    <origin rpy="0 0 0" xyz="0 0 0"/>
    <parent link="robot_base_link"/>
    <child link="robot_base"/>
  </joint>
  <transmission name="robot_tran1">
    <type>transmission_interface/SimpleTransmission</type>
    <joint name="robot_joint_1">
      <hardwareInterface>EffortJointInterface</hardwareInterface>
    </joint>
    <actuator name="robot_motor1">
      <hardwareInterface>EffortJointInterface</hardwareInterface>
      <mechanicalReduction>1</mechanicalReduction>
    </actuator>
  </transmission>
  <transmission name="robot_tran2">
    <type>transmission_interface/SimpleTransmission</type>
    <joint name="robot_joint_2">
      <hardwareInterface>EffortJointInterface</hardwareInterface>
    </joint>
    <actuator name="robot_motor2">
      <hardwareInterface>EffortJointInterface</hardwareInterface>
      <mechanicalReduction>1</mechanicalReduction>
    </actuator>
  </transmission>
  <transmission name="robot_tran3">
    <type>transmission_interface/SimpleTransmission</type>
    <joint name="robot_joint_3">
      <hardwareInterface>EffortJointInterface</hardwareInterface>
    </joint>
    <actuator name="robot_motor3">
      <hardwareInterface>EffortJointInterface</hardwareInterface>
      <mechanicalReduction>1</mechanicalReduction>
    </actuator>
  </transmission>
  <transmission name="robot_tran4">
    <type>transmission_interface/SimpleTransmission</type>
    <joint name="robot_joint_4">
      <hardwareInterface>EffortJointInterface</hardwareInterface>
    </joint>
    <actuator name="robot_motor4">
      <hardwareInterface>EffortJointInterface</hardwareInterface>
      <mechanicalReduction>1</mechanicalReduction>
    </actuator>
  </transmission>
  <transmission name="robot_tran5">
    <type>transmission_interface/SimpleTransmission</type>
    <joint name="robot_joint_5">
      <hardwareInterface>EffortJointInterface</hardwareInterface>
    </joint>
    <actuator name="robot_motor5">
      <hardwareInterface>EffortJointInterface</hardwareInterface>
      <mechanicalReduction>1</mechanicalReduction>
    </actuator>
  </transmission>
  <transmission name="robot_tran6">
    <type>transmission_interface/SimpleTransmission</type>
    <joint name="robot_joint_6">
      <hardwareInterface>EffortJointInterface</hardwareInterface>
    </joint>
    <actuator name="robot_motor6">
      <hardwareInterface>EffortJointInterface</hardwareInterface>
      <mechanicalReduction>1</mechanicalReduction>
    </actuator>
  </transmission>
  <gazebo reference="robot_base_link">
    <material>Gazebo/Orange</material>
    <turnGravityOff>true</turnGravityOff>
  </gazebo>
  <gazebo reference="robot_link_1">
    <material>Gazebo/Orange</material>
    <turnGravityOff>true</turnGravityOff>
  </gazebo>
  <gazebo reference="robot_link_2">
    <material>Gazebo/Orange</material>
    <turnGravityOff>true</turnGravityOff>
  </gazebo>
  <gazebo reference="robot_link_3">
    <material>Gazebo/Orange</material>
    <turnGravityOff>true</turnGravityOff>
  </gazebo>
  <gazebo reference="robot_link_4">
    <material>Gazebo/Orange</material>
    <turnGravityOff>true</turnGravityOff>
  </gazebo>
  <gazebo reference="robot_link_5">
    <material>Gazebo/Orange</material>
    <turnGravityOff>true</turnGravityOff>
  </gazebo>
  <gazebo reference="robot_link_6">
    <material>Gazebo/Black</material>
    <turnGravityOff>true</turnGravityOff>
  </gazebo>
  <gazebo>
    <plugin filename="libgazebo_ros_control.so" name="gazebo_ros_control">
      <robotNamespace>/</robotNamespace>
      <robotSimType>gazebo_ros_control/DefaultRobotHWSim</robotSimType>
    </plugin>
  </gazebo>
  <link name="world"/>
  <joint name="robot_fixed" type="fixed">
    <parent link="world"/>
    <child link="robot_base_link"/>
  </joint>
  <joint name="robotiq_robotiq_hand_joint" type="fixed">
    <origin rpy="0 0 -1.57079632679" xyz="0.054 0 0"/>
    <parent link="robot_tool0"/>
    <child link="robotiq_palm"/>
  </joint>
  <link name="robotiq_finger_1_link_0">
    <visual>
      <origin rpy="0 0 0" xyz="0 0 0"/>
      <geometry>
        <mesh filename="package://robotiq_s_model_visualization/meshes/s-model_articulated/visual/link_0.STL"/>
      </geometry>
      <material name="green">
        <color rgba="0 1 0 1"/>
      </material>
    </visual>
    <collision>
      <origin rpy="0 0 0" xyz="0 0 0"/>
      <geometry>
        <mesh filename="package://robotiq_s_model_visualization/meshes/s-model_articulated/collision/link_0.STL"/>
      </geometry>
      <material name="yellow">
        <color rgba="0 1 1 1"/>
      </material>
    </collision>
    <inertial>
      <mass value="0.1"/>
      <origin xyz="-0.01 0 0"/>
      <inertia ixx="0.000018" ixy="0" ixz="0" iyy="0.000025" iyz="0" izz="0.000025"/>
    </inertial>
  </link>
  <gazebo reference="robotiq_finger_1_link_0">
    <mu1>1.1</mu1>
    <mu2>1.1</mu2>
  </gazebo>
  <link name="robotiq_finger_1_link_1">
    <visual>
      <origin rpy="0 0 1.5708" xyz="0 0.05717 0"/>
      <geometry>
        <mesh filename="package://robotiq_s_model_visualization/meshes/s-model_articulated/visual/link_1.STL"/>
      </geometry>
      <material name="green"/>
    </visual>
    <collision>
      <origin rpy="0 0 1.5708" xyz="0 0.05717 0"/>
      <geometry>
        <mesh filename="package://robotiq_s_model_visualization/meshes/s-model_articulated/collision/link_1.STL"/>
      </geometry>
      <material name="yellow">
        <color rgba="0 1 1 1"/>
      </material>
    </collision>
    <inertial>
      <origin rpy="0 0 1.5708" xyz="0.00053 0.03218 0"/>
      <mass value="0.047"/>
      <inertia ixx="0.00000499332" ixy="0.00000091312" ixz="-0.00000000120" iyy="0.00006434531" iyz="-0.00000000007" izz="0.00006061917"/>
    </inertial>
  </link>
  <gazebo reference="robotiq_finger_1_link_1">
    <mu1>1.1</mu1>
    <mu2>1.1</mu2>
  </gazebo>
  <link name="robotiq_finger_1_link_2">
    <visual>
      <origin rpy="0 0 1.5708" xyz="0 0.03810 0.0075"/>
      <geometry>
        <mesh filename="package://robotiq_s_model_visualization/meshes/s-model_articulated/visual/link_2.STL"/>
      </geometry>
      <material name="green"/>
    </visual>
    <collision>
      <origin rpy="0 0 1.5708" xyz="0 0.03810 0.0075"/>
      <geometry>
        <mesh filename="package://robotiq_s_model_visualization/meshes/s-model_articulated/collision/link_2.STL"/>
      </geometry>
      <material name="yellow"/>
    </collision>
    <inertial>
      <origin rpy="0 0 1.5708" xyz="0.00048 0.02167 0.00018"/>
      <mass value="0.03284"/>
      <inertia ixx="0.00000348008" ixy="0.00000031940" ixz="0.00000013041" iyy="0.00002248123" iyz="0.00000000291" izz="0.00001986346"/>
    </inertial>
  </link>
  <gazebo reference="robotiq_finger_1_link_2">
    <mu1>1.1</mu1>
    <mu2>1.1</mu2>
  </gazebo>
  <link name="robotiq_finger_1_link_3">
    <visual>
      <origin rpy="0 0 0" xyz="0 0 0"/>
      <geometry>
        <mesh filename="package://robotiq_s_model_visualization/meshes/s-model_articulated/visual/link_3.STL"/>
      </geometry>
      <material name="green"/>
    </visual>
    <collision>
      <origin rpy="0 0 0" xyz="0 0 0"/>
      <geometry>
        <mesh filename="package://robotiq_s_model_visualization/meshes/s-model_articulated/collision/link_3.STL"/>
      </geometry>
      <material name="yellow"/>
    </collision>
    <inertial>
      <origin rpy="0 0 0" xyz="0.01626 0.00049 0.0002"/>
      <mass value="0.03354"/>
      <inertia ixx="0.00000305151" ixy="0.00000089792" ixz="0.00000000249" iyy="0.00001427978" iyz="-0.00000001191" izz="0.00001264126"/>
    </inertial>
  </link>
  <gazebo reference="robotiq_finger_1_link_3">
    <mu1>1.1</mu1>
    <mu2>1.1</mu2>
  </gazebo>
  <link name="robotiq_finger_1_link_proximal_actuating_hinge">
    <visual>
      <origin rpy="0 0 0" xyz="0.01429 0 0"/>
      <geometry>
        <box size="0.02858 .0075 .002"/>
      </geometry>
    </visual>
    <collision>
      <origin rpy="0 0 0" xyz="0.01429 0 0"/>
      <geometry>
        <box size="0.02858 .0075 .002"/>
      </geometry>
    </collision>
    <inertial>
      <origin rpy="0 0 0" xyz="0.0012 -0.00162 -0.00161"/>
      <mass value="0.02647"/>
      <inertia ixx="0.00000156447" ixy="0.000000236226" ixz="-0.00000014862" iyy="0.00000221068" iyz="-0.00000014369" izz="0.00000323175"/>
    </inertial>
  </link>
  <gazebo reference="robotiq_finger_1_link_proximal_actuating_hinge">
    <mu1>1.1</mu1>
    <mu2>1.1</mu2>
  </gazebo>
  <link name="robotiq_finger_1_link_paraproximal_actuating_hinge">
    <visual>
      <origin rpy="0 0 0" xyz="0.01143 0 0"/>
      <geometry>
        <box size="0.02286 .0075 .002"/>
      </geometry>
    </visual>
    <collision>
      <origin rpy="0 0 0" xyz="0.01143 0 0"/>
      <geometry>
        <box size="0.02286 .0075 .002"/>
      </geometry>
    </collision>
    <inertial>
      <origin rpy="0 0 0" xyz="0.0064 0 0"/>
      <!-- copied from proximal_actuating_hinge -->
      <mass value="0.00362"/>
      <inertia ixx="0.00000012043" ixy="0" ixz="0" iyy="0.00000053588" iyz="0" izz="0.00000065322"/>
    </inertial>
  </link>
  <gazebo reference="robotiq_finger_1_link_paraproximal_actuating_hinge">
    <mu1>1.1</mu1>
    <mu2>1.1</mu2>
  </gazebo>
  <link name="robotiq_finger_1_link_proximal_actuating_bar">
    <visual>
      <origin rpy="0 0 0" xyz="0.026789 0 0"/>
      <geometry>
        <box size="0.05398 .0075 .002"/>
      </geometry>
    </visual>
    <collision>
      <origin rpy="0 0 0" xyz="0.026789 0 0"/>
      <geometry>
        <box size="0.05398 .0075 .002"/>
      </geometry>
    </collision>
    <inertial>
      <origin rpy="0 0 0" xyz="0.02699 -0.00122 0"/>
      <mass value="0.00659"/>
      <inertia ixx="0.00000008348" ixy="-0.0000002179" ixz="0.00000000134" iyy="0.00000719076" iyz="0" izz="0.00000718272"/>
    </inertial>
  </link>
  <gazebo reference="robotiq_finger_1_link_proximal_actuating_bar">
    <mu1>1.1</mu1>
    <mu2>1.1</mu2>
  </gazebo>
  <link name="robotiq_finger_1_link_paraproximal_bar">
    <visual>
      <origin rpy="0 0 0" xyz="0.02885 0 0"/>
      <geometry>
        <box size="0.05770 .0075 .002"/>
      </geometry>
    </visual>
    <collision>
      <origin rpy="0 0 0" xyz="0.02885 0 0"/>
      <geometry>
        <box size="0.05770 .0075 .002"/>
      </geometry>
    </collision>
    <inertial>
      <origin rpy="0 0 0" xyz="0.02858 -0.00129 0"/>
      <mass value="0.00732"/>
      <inertia ixx="0.00000009065" ixy="-0.00000027047" ixz="0.00000000142" iyy="0.00000878034" iyz="0" izz="0.00000877558"/>
    </inertial>
  </link>
  <gazebo reference="robotiq_finger_1_link_paraproximal_bar">
    <mu1>1.1</mu1>
    <mu2>1.1</mu2>
  </gazebo>
  <link name="robotiq_finger_1_link_median_actuating_hinge">
    <visual>
      <origin rpy="0 0 0" xyz="0 0 0"/>
      <geometry>
        <box size=".02 .02 .002"/>
      </geometry>
    </visual>
    <collision>
      <origin rpy="0 0 0" xyz="0 0 0"/>
      <geometry>
        <box size=".02 .02 .002"/>
      </geometry>
    </collision>
    <inertial>
      <origin rpy="0 0 0" xyz="0.0092 0.00514 0"/>
      <mass value="0.00359"/>
      <inertia ixx="0.00000024735" ixy="0.00000023619" ixz="0" iyy="0.00000047681" iyz="0" izz="0.00000071813"/>
    </inertial>
  </link>
  <gazebo reference="robotiq_finger_1_link_median_actuating_hinge">
    <mu1>1.1</mu1>
    <mu2>1.1</mu2>
  </gazebo>
  <link name="robotiq_finger_1_link_median_bar">
    <visual>
      <origin rpy="0 0 0" xyz="0.01905 0 0"/>
      <geometry>
        <box size="0.0381 .0075 .002"/>
      </geometry>
    </visual>
    <collision>
      <origin rpy="0 0 0" xyz="0.01905 0 0"/>
      <geometry>
        <box size="0.0381 .0075 .002"/>
      </geometry>
    </collision>
    <inertial>
      <origin rpy="0 0 0" xyz="0.01905 -0.00107 0"/>
      <mass value="0.00538"/>
      <inertia ixx="0.00000006639" ixy="-0.00000010996" ixz="0.00000000094" iyy="0.00000305318" iyz="0" izz="0.00000304657"/>
    </inertial>
  </link>
  <gazebo reference="robotiq_finger_1_link_median_bar">
    <mu1>1.1</mu1>
    <mu2>1.1</mu2>
  </gazebo>
  <link name="robotiq_finger_1_link_paramedian_hinge">
    <visual>
      <origin rpy="0 0 0" xyz="0 0 0"/>
      <geometry>
        <box size=".02 .02 .002"/>
      </geometry>
    </visual>
    <collision>
      <origin rpy="0 0 0" xyz="0 0 0"/>
      <geometry>
        <box size=".02 .02 .002"/>
      </geometry>
    </collision>
    <inertial>
      <origin rpy="0 0 0" xyz="-0.01025 0.00046 0"/>
      <mass value="0.00276"/>
      <inertia ixx="0.00000004213" ixy="-0.00000001491" ixz="0" iyy="0.00000050258" iyz="0" izz="0.00000054007"/>
    </inertial>
  </link>
  <gazebo reference="robotiq_finger_1_link_paramedian_hinge">
    <mu1>1.1</mu1>
    <mu2>1.1</mu2>
  </gazebo>
  <link name="robotiq_finger_1_link_median_bar_underactuated">
    <visual>
      <origin rpy="0 0 0" xyz="0.01905 0 0"/>
      <geometry>
        <box size="0.0381 .0075 .002"/>
      </geometry>
    </visual>
    <collision>
      <origin rpy="0 0 0" xyz="0.01905 0 0"/>
      <geometry>
        <box size="0.0381 .0075 .002"/>
      </geometry>
    </collision>
    <inertial>
      <origin rpy="0 0 0" xyz="0.01905 -0.00107 0"/>
      <mass value="0.00538"/>
      <inertia ixx="0.00000006639" ixy="-0.00000010996" ixz="-0.00000000094" iyy="0.00000305318" iyz="0" izz="0.00000304657"/>
    </inertial>
  </link>
  <gazebo reference="robotiq_finger_1_link_median_bar_underactuated">
    <mu1>1.1</mu1>
    <mu2>1.1</mu2>
  </gazebo>
  <link name="robotiq_finger_1_link_paradistal_hinge">
    <visual>
      <origin rpy="0 0 0" xyz="0 0 0"/>
      <geometry>
        <box size=".02 .02 .002"/>
      </geometry>
    </visual>
    <collision>
      <origin rpy="0 0 0" xyz="0 0 0"/>
      <geometry>
        <box size=".02 0.02 .002"/>
      </geometry>
    </collision>
    <inertial>
      <origin rpy="0 0 0" xyz="0.00548 0 0"/>
      <mass value="0.00158"/>
      <inertia ixx="0.00000001907" ixy="0" ixz="0" iyy="0.00000010970" iyz="0" izz="0.00000012610"/>
    </inertial>
  </link>
  <gazebo reference="robotiq_finger_1_link_paradistal_hinge">
    <mu1>1.1</mu1>
    <mu2>1.1</mu2>
  </gazebo>
  <joint name="robotiq_finger_1_joint_proximal_actuating_hinge" type="revolute">
    <parent link="robotiq_finger_1_link_0"/>
    <child link="robotiq_finger_1_link_proximal_actuating_hinge"/>
    <axis xyz="0 0 1"/>
    <origin rpy="0 0 -2.0906" xyz="0 0 0.01"/>
    <limit effort="100" lower="-3.1416" upper="3.1416" velocity="100"/>
  </joint>
  <gazebo reference="robotiq_finger_1_joint_proximal_actuating_hinge">
    <implicitSpringDamper>1</implicitSpringDamper>
  </gazebo>
  <joint name="robotiq_finger_1_joint_paraproximal_actuating_hinge" type="revolute">
    <parent link="robotiq_finger_1_link_0"/>
    <child link="robotiq_finger_1_link_paraproximal_actuating_hinge"/>
    <axis xyz="0 0 1"/>
    <origin rpy="0 0 -2.0906" xyz="0 0 -0.01"/>
    <limit effort="100" lower="-3.1416" upper="3.1416" velocity="100"/>
  </joint>
  <gazebo reference="robotiq_finger_1_joint_paraproximal_actuating_hinge">
    <implicitSpringDamper>1</implicitSpringDamper>
  </gazebo>
  <joint name="robotiq_finger_1_joint_proximal_actuating_bar" type="revolute">
    <parent link="robotiq_finger_1_link_proximal_actuating_hinge"/>
    <child link="robotiq_finger_1_link_proximal_actuating_bar"/>
    <axis xyz="0 0 1"/>
    <origin rpy="0 0 1.8616" xyz="0.02858 0 0"/>
    <limit effort="100" lower="-3.1416" upper="3.1416" velocity="100"/>
  </joint>
  <gazebo reference="robotiq_finger_1_joint_proximal_actuating_bar">
    <implicitSpringDamper>1</implicitSpringDamper>
  </gazebo>
  <joint name="robotiq_finger_1_joint_paraproximal_bar" type="revolute">
    <parent link="robotiq_finger_1_link_paraproximal_actuating_hinge"/>
    <child link="robotiq_finger_1_link_paraproximal_bar"/>
    <axis xyz="0 0 1"/>
    <origin rpy="0 0 1.57" xyz="0.02286 0 0"/>
    <limit effort="100" lower="-3.1416" upper="3.1416" velocity="100"/>
  </joint>
  <gazebo reference="robotiq_finger_1_joint_paraproximal_bar">
    <implicitSpringDamper>1</implicitSpringDamper>
  </gazebo>
  <joint name="robotiq_finger_1_joint_median_actuating_hinge" type="revolute">
    <parent link="robotiq_finger_1_link_1"/>
    <child link="robotiq_finger_1_link_median_actuating_hinge"/>
    <axis xyz="0 0 1"/>
    <origin rpy="0 0 -0.37" xyz="0 0.05715 0.01"/>
    <limit effort="100" lower="-3.1416" upper="3.1416" velocity="100"/>
  </joint>
  <gazebo reference="robotiq_finger_1_joint_median_actuating_hinge">
    <implicitSpringDamper>1</implicitSpringDamper>
  </gazebo>
  <joint name="robotiq_finger_1_joint_paramedian_hinge" type="revolute">
    <parent link="robotiq_finger_1_link_1"/>
    <child link="robotiq_finger_1_link_paramedian_hinge"/>
    <axis xyz="0 0 1"/>
    <!-- -0.37 is hand picked, 0.9719 is hand calculated from atan(0.02381/0.01625) -->
    <origin rpy="0 0 0" xyz="0 0.05715 -0.01"/>
    <limit effort="100" lower="-3.1416" upper="3.1416" velocity="100"/>
  </joint>
  <gazebo reference="robotiq_finger_1_joint_paramedian_hinge">
    <implicitSpringDamper>1</implicitSpringDamper>
  </gazebo>
  <joint name="robotiq_finger_1_joint_median_actuating_hinge_median_bar" type="revolute">
    <parent link="robotiq_finger_1_link_median_actuating_hinge"/>
    <child link="robotiq_finger_1_link_median_bar"/>
    <axis xyz="0 0 1"/>
    <!-- hand calc 90 deg + atan(0.01516/0.01625) -->
    <origin rpy="0 0 2.3215" xyz="0.01625 0.01516 0"/>
    <limit effort="100" lower="-3.1416" upper="3.1416" velocity="100"/>
  </joint>
  <gazebo reference="robotiq_finger_1_joint_median_actuating_hinge_median_bar">
    <implicitSpringDamper>1</implicitSpringDamper>
  </gazebo>
  <joint name="robotiq_finger_1_joint_paradistal_hinge" type="revolute">
    <parent link="robotiq_finger_1_link_2"/>
    <child link="robotiq_finger_1_link_paradistal_hinge"/>
    <axis xyz="0 0 1"/>
    <origin rpy="0 0 0" xyz="0 0.039 -0.01"/>
    <limit effort="100" lower="-3.1416" upper="3.1416" velocity="100"/>
  </joint>
  <gazebo reference="robotiq_finger_1_joint_paradistal_hinge">
    <implicitSpringDamper>1</implicitSpringDamper>
  </gazebo>
  <joint name="robotiq_finger_1_joint_paramedian_hinge_median_bar_underactuated" type="revolute">
    <parent link="robotiq_finger_1_link_paramedian_hinge"/>
    <child link="robotiq_finger_1_link_median_bar_underactuated"/>
    <axis xyz="0 0 1"/>
    <!-- hand calc 90 deg + atan(0.01227/0.00329) -->
    <origin rpy="0 0 1.5708" xyz="0.01227 0.00329 0"/>
    <limit effort="100" lower="-3.1416" upper="3.1416" velocity="100"/>
  </joint>
  <gazebo reference="robotiq_finger_1_joint_paramedian_hinge_median_bar_underactuated">
    <implicitSpringDamper>1</implicitSpringDamper>
  </gazebo>
  <joint name="robotiq_finger_1_joint_1" type="revolute">
    <origin rpy="0 0 -2.0906" xyz="0 0 0"/>
    <axis xyz="0 0 1"/>
    <parent link="robotiq_finger_1_link_0"/>
    <child link="robotiq_finger_1_link_1"/>
    <dynamics damping="1" friction="0"/>
    <!-- Limits: [0deg.,70deg.] -->
    <limit effort="60" lower="0" upper="1.2217" velocity="-1"/>
  </joint>
  <gazebo reference="robotiq_finger_1_joint_1">
    <implicitSpringDamper>1</implicitSpringDamper>
  </gazebo>
  <joint name="robotiq_finger_1_joint_2" type="revolute">
    <parent link="robotiq_finger_1_link_1"/>
    <child link="robotiq_finger_1_link_2"/>
    <dynamics damping="1" friction="0"/>
    <axis xyz="0 0 1"/>
    <origin rpy="0 0 0" xyz="0 0.05715 0"/>
    <!-- Limits: [0deg.,90deg.] -->
    <limit effort="60" lower="0" upper="1.5708" velocity="-1"/>
  </joint>
  <gazebo reference="robotiq_finger_1_joint_2">
    <implicitSpringDamper>1</implicitSpringDamper>
  </gazebo>
  <joint name="robotiq_finger_1_joint_3" type="revolute">
    <parent link="robotiq_finger_1_link_2"/>
    <child link="robotiq_finger_1_link_3"/>
    <dynamics damping="1" friction="0"/>
    <axis xyz="0 0 1"/>
    <origin rpy="0 0 2.0906" xyz="0 0.039 0"/>
    <!-- Limits: [-38deg.,60deg.] -->
    <limit effort="60" lower="-0.6632" upper="1.0471" velocity="-1"/>
  </joint>
  <gazebo reference="robotiq_finger_1_joint_3">
    <implicitSpringDamper>1</implicitSpringDamper>
  </gazebo>
  <gazebo>
    <joint name="robotiq_finger_1_link_proximal_actuating_bar_median_actuating_hinge_couple" type="revolute">
      <parent>robotiq_finger_1_link_median_actuating_hinge</parent>
      <child>robotiq_finger_1_link_proximal_actuating_bar</child>
      <pose>0.05398 0 0 0 0 0</pose>
      <axis>
        <dynamics>
          <damping>0</damping>
          <friction>0</friction>
        </dynamics>
        <xyz>0 0 1</xyz>
        <!-- <use_parent_model_frame>false</use_parent_model_frame> -->
      </axis>
    </joint>
  </gazebo>
  <gazebo reference="robotiq_finger_1_link_proximal_actuating_bar_median_actuating_hinge_couple">
    <implicitSpringDamper>1</implicitSpringDamper>
  </gazebo>
  <gazebo>
    <joint name="robotiq_finger_1_link_median_bar_link_3_couple" type="revolute">
      <parent>robotiq_finger_1_link_3</parent>
      <child>robotiq_finger_1_link_median_bar</child>
      <pose>0.0381 0 0 0 0 0</pose>
      <axis>
        <dynamics>
          <damping>0</damping>
          <friction>0</friction>
        </dynamics>
        <xyz>0 0 1</xyz>
        <!-- <use_parent_model_frame>false</use_parent_model_frame> -->
      </axis>
    </joint>
  </gazebo>
  <gazebo reference="robotiq_finger_1_link_median_bar_link_3_couple">
    <implicitSpringDamper>1</implicitSpringDamper>
  </gazebo>
  <gazebo>
    <joint name="robotiq_finger_1_link_paramedian_bar_paradistal_hinge_couple" type="revolute">
      <parent>robotiq_finger_1_link_paradistal_hinge</parent>
      <child>robotiq_finger_1_link_median_bar_underactuated</child>
      <pose>0.0381 0 0 0 0 0</pose>
      <axis>
        <dynamics>
          <damping>0</damping>
          <friction>0</friction>
        </dynamics>
        <xyz>0 0 1</xyz>
        <!-- <use_parent_model_frame>false</use_parent_model_frame> -->
      </axis>
    </joint>
  </gazebo>
  <gazebo reference="robotiq_finger_1_link_median_bar_link_3_couple">
    <implicitSpringDamper>1</implicitSpringDamper>
  </gazebo>
  <gazebo>
    <joint name="robotiq_finger_1_link_paradistal_hinge_link_3_couple" type="revolute">
      <parent>robotiq_finger_1_link_paradistal_hinge</parent>
      <child>robotiq_finger_1_link_3</child>
      <pose>0.0381 0 0 0 0 0</pose>
      <axis>
        <dynamics>
          <damping>0</damping>
          <friction>0</friction>
        </dynamics>
        <xyz>0 0 1</xyz>
        <!-- <use_parent_model_frame>false</use_parent_model_frame> -->
      </axis>
    </joint>
  </gazebo>
  <gazebo reference="robotiq_finger_1_link_paradistal_hinge_link_3_couple">
    <implicitSpringDamper>1</implicitSpringDamper>
  </gazebo>
  <gazebo>
    <joint name="robotiq_finger_1_link_paraproximal_bar_paramedian_hinge_couple" type="revolute">
      <parent>robotiq_finger_1_link_paramedian_hinge</parent>
      <child>robotiq_finger_1_link_paraproximal_bar</child>
      <pose>0.05770 0 0 0 0 0</pose>
      <axis>
        <dynamics>
          <damping>0</damping>
          <friction>0</friction>
        </dynamics>
        <xyz>0 0 1</xyz>
        <!-- <use_parent_model_frame>false</use_parent_model_frame> -->
      </axis>
    </joint>
  </gazebo>
  <gazebo reference="robotiq_finger_1_link_paraproximal_bar_paramedian_hinge_couple">
    <implicitSpringDamper>1</implicitSpringDamper>
  </gazebo>
  <link name="robotiq_finger_2_link_0">
    <visual>
      <origin rpy="0 0 0" xyz="0 0 0"/>
      <geometry>
        <mesh filename="package://robotiq_s_model_visualization/meshes/s-model_articulated/visual/link_0.STL"/>
      </geometry>
      <material name="green">
        <color rgba="0 1 0 1"/>
      </material>
    </visual>
    <collision>
      <origin rpy="0 0 0" xyz="0 0 0"/>
      <geometry>
        <mesh filename="package://robotiq_s_model_visualization/meshes/s-model_articulated/collision/link_0.STL"/>
      </geometry>
      <material name="yellow">
        <color rgba="0 1 1 1"/>
      </material>
    </collision>
    <inertial>
      <mass value="0.1"/>
      <origin xyz="-0.01 0 0"/>
      <inertia ixx="0.000018" ixy="0" ixz="0" iyy="0.000025" iyz="0" izz="0.000025"/>
    </inertial>
  </link>
  <gazebo reference="robotiq_finger_2_link_0">
    <mu1>1.1</mu1>
    <mu2>1.1</mu2>
  </gazebo>
  <link name="robotiq_finger_2_link_1">
    <visual>
      <origin rpy="0 0 1.5708" xyz="0 0.05717 0"/>
      <geometry>
        <mesh filename="package://robotiq_s_model_visualization/meshes/s-model_articulated/visual/link_1.STL"/>
      </geometry>
      <material name="green"/>
    </visual>
    <collision>
      <origin rpy="0 0 1.5708" xyz="0 0.05717 0"/>
      <geometry>
        <mesh filename="package://robotiq_s_model_visualization/meshes/s-model_articulated/collision/link_1.STL"/>
      </geometry>
      <material name="yellow">
        <color rgba="0 1 1 1"/>
      </material>
    </collision>
    <inertial>
      <origin rpy="0 0 1.5708" xyz="0.00053 0.03218 0"/>
      <mass value="0.047"/>
      <inertia ixx="0.00000499332" ixy="0.00000091312" ixz="-0.00000000120" iyy="0.00006434531" iyz="-0.00000000007" izz="0.00006061917"/>
    </inertial>
  </link>
  <gazebo reference="robotiq_finger_2_link_1">
    <mu1>1.1</mu1>
    <mu2>1.1</mu2>
  </gazebo>
  <link name="robotiq_finger_2_link_2">
    <visual>
      <origin rpy="0 0 1.5708" xyz="0 0.03810 0.0075"/>
      <geometry>
        <mesh filename="package://robotiq_s_model_visualization/meshes/s-model_articulated/visual/link_2.STL"/>
      </geometry>
      <material name="green"/>
    </visual>
    <collision>
      <origin rpy="0 0 1.5708" xyz="0 0.03810 0.0075"/>
      <geometry>
        <mesh filename="package://robotiq_s_model_visualization/meshes/s-model_articulated/collision/link_2.STL"/>
      </geometry>
      <material name="yellow"/>
    </collision>
    <inertial>
      <origin rpy="0 0 1.5708" xyz="0.00048 0.02167 0.00018"/>
      <mass value="0.03284"/>
      <inertia ixx="0.00000348008" ixy="0.00000031940" ixz="0.00000013041" iyy="0.00002248123" iyz="0.00000000291" izz="0.00001986346"/>
    </inertial>
  </link>
  <gazebo reference="robotiq_finger_2_link_2">
    <mu1>1.1</mu1>
    <mu2>1.1</mu2>
  </gazebo>
  <link name="robotiq_finger_2_link_3">
    <visual>
      <origin rpy="0 0 0" xyz="0 0 0"/>
      <geometry>
        <mesh filename="package://robotiq_s_model_visualization/meshes/s-model_articulated/visual/link_3.STL"/>
      </geometry>
      <material name="green"/>
    </visual>
    <collision>
      <origin rpy="0 0 0" xyz="0 0 0"/>
      <geometry>
        <mesh filename="package://robotiq_s_model_visualization/meshes/s-model_articulated/collision/link_3.STL"/>
      </geometry>
      <material name="yellow"/>
    </collision>
    <inertial>
      <origin rpy="0 0 0" xyz="0.01626 0.00049 0.0002"/>
      <mass value="0.03354"/>
      <inertia ixx="0.00000305151" ixy="0.00000089792" ixz="0.00000000249" iyy="0.00001427978" iyz="-0.00000001191" izz="0.00001264126"/>
    </inertial>
  </link>
  <gazebo reference="robotiq_finger_2_link_3">
    <mu1>1.1</mu1>
    <mu2>1.1</mu2>
  </gazebo>
  <link name="robotiq_finger_2_link_proximal_actuating_hinge">
    <visual>
      <origin rpy="0 0 0" xyz="0.01429 0 0"/>
      <geometry>
        <box size="0.02858 .0075 .002"/>
      </geometry>
    </visual>
    <collision>
      <origin rpy="0 0 0" xyz="0.01429 0 0"/>
      <geometry>
        <box size="0.02858 .0075 .002"/>
      </geometry>
    </collision>
    <inertial>
      <origin rpy="0 0 0" xyz="0.0012 -0.00162 -0.00161"/>
      <mass value="0.02647"/>
      <inertia ixx="0.00000156447" ixy="0.000000236226" ixz="-0.00000014862" iyy="0.00000221068" iyz="-0.00000014369" izz="0.00000323175"/>
    </inertial>
  </link>
  <gazebo reference="robotiq_finger_2_link_proximal_actuating_hinge">
    <mu1>1.1</mu1>
    <mu2>1.1</mu2>
  </gazebo>
  <link name="robotiq_finger_2_link_paraproximal_actuating_hinge">
    <visual>
      <origin rpy="0 0 0" xyz="0.01143 0 0"/>
      <geometry>
        <box size="0.02286 .0075 .002"/>
      </geometry>
    </visual>
    <collision>
      <origin rpy="0 0 0" xyz="0.01143 0 0"/>
      <geometry>
        <box size="0.02286 .0075 .002"/>
      </geometry>
    </collision>
    <inertial>
      <origin rpy="0 0 0" xyz="0.0064 0 0"/>
      <!-- copied from proximal_actuating_hinge -->
      <mass value="0.00362"/>
      <inertia ixx="0.00000012043" ixy="0" ixz="0" iyy="0.00000053588" iyz="0" izz="0.00000065322"/>
    </inertial>
  </link>
  <gazebo reference="robotiq_finger_2_link_paraproximal_actuating_hinge">
    <mu1>1.1</mu1>
    <mu2>1.1</mu2>
  </gazebo>
  <link name="robotiq_finger_2_link_proximal_actuating_bar">
    <visual>
      <origin rpy="0 0 0" xyz="0.026789 0 0"/>
      <geometry>
        <box size="0.05398 .0075 .002"/>
      </geometry>
    </visual>
    <collision>
      <origin rpy="0 0 0" xyz="0.026789 0 0"/>
      <geometry>
        <box size="0.05398 .0075 .002"/>
      </geometry>
    </collision>
    <inertial>
      <origin rpy="0 0 0" xyz="0.02699 -0.00122 0"/>
      <mass value="0.00659"/>
      <inertia ixx="0.00000008348" ixy="-0.0000002179" ixz="0.00000000134" iyy="0.00000719076" iyz="0" izz="0.00000718272"/>
    </inertial>
  </link>
  <gazebo reference="robotiq_finger_2_link_proximal_actuating_bar">
    <mu1>1.1</mu1>
    <mu2>1.1</mu2>
  </gazebo>
  <link name="robotiq_finger_2_link_paraproximal_bar">
    <visual>
      <origin rpy="0 0 0" xyz="0.02885 0 0"/>
      <geometry>
        <box size="0.05770 .0075 .002"/>
      </geometry>
    </visual>
    <collision>
      <origin rpy="0 0 0" xyz="0.02885 0 0"/>
      <geometry>
        <box size="0.05770 .0075 .002"/>
      </geometry>
    </collision>
    <inertial>
      <origin rpy="0 0 0" xyz="0.02858 -0.00129 0"/>
      <mass value="0.00732"/>
      <inertia ixx="0.00000009065" ixy="-0.00000027047" ixz="0.00000000142" iyy="0.00000878034" iyz="0" izz="0.00000877558"/>
    </inertial>
  </link>
  <gazebo reference="robotiq_finger_2_link_paraproximal_bar">
    <mu1>1.1</mu1>
    <mu2>1.1</mu2>
  </gazebo>
  <link name="robotiq_finger_2_link_median_actuating_hinge">
    <visual>
      <origin rpy="0 0 0" xyz="0 0 0"/>
      <geometry>
        <box size=".02 .02 .002"/>
      </geometry>
    </visual>
    <collision>
      <origin rpy="0 0 0" xyz="0 0 0"/>
      <geometry>
        <box size=".02 .02 .002"/>
      </geometry>
    </collision>
    <inertial>
      <origin rpy="0 0 0" xyz="0.0092 0.00514 0"/>
      <mass value="0.00359"/>
      <inertia ixx="0.00000024735" ixy="0.00000023619" ixz="0" iyy="0.00000047681" iyz="0" izz="0.00000071813"/>
    </inertial>
  </link>
  <gazebo reference="robotiq_finger_2_link_median_actuating_hinge">
    <mu1>1.1</mu1>
    <mu2>1.1</mu2>
  </gazebo>
  <link name="robotiq_finger_2_link_median_bar">
    <visual>
      <origin rpy="0 0 0" xyz="0.01905 0 0"/>
      <geometry>
        <box size="0.0381 .0075 .002"/>
      </geometry>
    </visual>
    <collision>
      <origin rpy="0 0 0" xyz="0.01905 0 0"/>
      <geometry>
        <box size="0.0381 .0075 .002"/>
      </geometry>
    </collision>
    <inertial>
      <origin rpy="0 0 0" xyz="0.01905 -0.00107 0"/>
      <mass value="0.00538"/>
      <inertia ixx="0.00000006639" ixy="-0.00000010996" ixz="0.00000000094" iyy="0.00000305318" iyz="0" izz="0.00000304657"/>
    </inertial>
  </link>
  <gazebo reference="robotiq_finger_2_link_median_bar">
    <mu1>1.1</mu1>
    <mu2>1.1</mu2>
  </gazebo>
  <link name="robotiq_finger_2_link_paramedian_hinge">
    <visual>
      <origin rpy="0 0 0" xyz="0 0 0"/>
      <geometry>
        <box size=".02 .02 .002"/>
      </geometry>
    </visual>
    <collision>
      <origin rpy="0 0 0" xyz="0 0 0"/>
      <geometry>
        <box size=".02 .02 .002"/>
      </geometry>
    </collision>
    <inertial>
      <origin rpy="0 0 0" xyz="-0.01025 0.00046 0"/>
      <mass value="0.00276"/>
      <inertia ixx="0.00000004213" ixy="-0.00000001491" ixz="0" iyy="0.00000050258" iyz="0" izz="0.00000054007"/>
    </inertial>
  </link>
  <gazebo reference="robotiq_finger_2_link_paramedian_hinge">
    <mu1>1.1</mu1>
    <mu2>1.1</mu2>
  </gazebo>
  <link name="robotiq_finger_2_link_median_bar_underactuated">
    <visual>
      <origin rpy="0 0 0" xyz="0.01905 0 0"/>
      <geometry>
        <box size="0.0381 .0075 .002"/>
      </geometry>
    </visual>
    <collision>
      <origin rpy="0 0 0" xyz="0.01905 0 0"/>
      <geometry>
        <box size="0.0381 .0075 .002"/>
      </geometry>
    </collision>
    <inertial>
      <origin rpy="0 0 0" xyz="0.01905 -0.00107 0"/>
      <mass value="0.00538"/>
      <inertia ixx="0.00000006639" ixy="-0.00000010996" ixz="-0.00000000094" iyy="0.00000305318" iyz="0" izz="0.00000304657"/>
    </inertial>
  </link>
  <gazebo reference="robotiq_finger_2_link_median_bar_underactuated">
    <mu1>1.1</mu1>
    <mu2>1.1</mu2>
  </gazebo>
  <link name="robotiq_finger_2_link_paradistal_hinge">
    <visual>
      <origin rpy="0 0 0" xyz="0 0 0"/>
      <geometry>
        <box size=".02 .02 .002"/>
      </geometry>
    </visual>
    <collision>
      <origin rpy="0 0 0" xyz="0 0 0"/>
      <geometry>
        <box size=".02 0.02 .002"/>
      </geometry>
    </collision>
    <inertial>
      <origin rpy="0 0 0" xyz="0.00548 0 0"/>
      <mass value="0.00158"/>
      <inertia ixx="0.00000001907" ixy="0" ixz="0" iyy="0.00000010970" iyz="0" izz="0.00000012610"/>
    </inertial>
  </link>
  <gazebo reference="robotiq_finger_2_link_paradistal_hinge">
    <mu1>1.1</mu1>
    <mu2>1.1</mu2>
  </gazebo>
  <joint name="robotiq_finger_2_joint_proximal_actuating_hinge" type="revolute">
    <parent link="robotiq_finger_2_link_0"/>
    <child link="robotiq_finger_2_link_proximal_actuating_hinge"/>
    <axis xyz="0 0 1"/>
    <origin rpy="0 0 -2.0906" xyz="0 0 0.01"/>
    <limit effort="100" lower="-3.1416" upper="3.1416" velocity="100"/>
  </joint>
  <gazebo reference="robotiq_finger_2_joint_proximal_actuating_hinge">
    <implicitSpringDamper>1</implicitSpringDamper>
  </gazebo>
  <joint name="robotiq_finger_2_joint_paraproximal_actuating_hinge" type="revolute">
    <parent link="robotiq_finger_2_link_0"/>
    <child link="robotiq_finger_2_link_paraproximal_actuating_hinge"/>
    <axis xyz="0 0 1"/>
    <origin rpy="0 0 -2.0906" xyz="0 0 -0.01"/>
    <limit effort="100" lower="-3.1416" upper="3.1416" velocity="100"/>
  </joint>
  <gazebo reference="robotiq_finger_2_joint_paraproximal_actuating_hinge">
    <implicitSpringDamper>1</implicitSpringDamper>
  </gazebo>
  <joint name="robotiq_finger_2_joint_proximal_actuating_bar" type="revolute">
    <parent link="robotiq_finger_2_link_proximal_actuating_hinge"/>
    <child link="robotiq_finger_2_link_proximal_actuating_bar"/>
    <axis xyz="0 0 1"/>
    <origin rpy="0 0 1.8616" xyz="0.02858 0 0"/>
    <limit effort="100" lower="-3.1416" upper="3.1416" velocity="100"/>
  </joint>
  <gazebo reference="robotiq_finger_2_joint_proximal_actuating_bar">
    <implicitSpringDamper>1</implicitSpringDamper>
  </gazebo>
  <joint name="robotiq_finger_2_joint_paraproximal_bar" type="revolute">
    <parent link="robotiq_finger_2_link_paraproximal_actuating_hinge"/>
    <child link="robotiq_finger_2_link_paraproximal_bar"/>
    <axis xyz="0 0 1"/>
    <origin rpy="0 0 1.57" xyz="0.02286 0 0"/>
    <limit effort="100" lower="-3.1416" upper="3.1416" velocity="100"/>
  </joint>
  <gazebo reference="robotiq_finger_2_joint_paraproximal_bar">
    <implicitSpringDamper>1</implicitSpringDamper>
  </gazebo>
  <joint name="robotiq_finger_2_joint_median_actuating_hinge" type="revolute">
    <parent link="robotiq_finger_2_link_1"/>
    <child link="robotiq_finger_2_link_median_actuating_hinge"/>
    <axis xyz="0 0 1"/>
    <origin rpy="0 0 -0.37" xyz="0 0.05715 0.01"/>
    <limit effort="100" lower="-3.1416" upper="3.1416" velocity="100"/>
  </joint>
  <gazebo reference="robotiq_finger_2_joint_median_actuating_hinge">
    <implicitSpringDamper>1</implicitSpringDamper>
  </gazebo>
  <joint name="robotiq_finger_2_joint_paramedian_hinge" type="revolute">
    <parent link="robotiq_finger_2_link_1"/>
    <child link="robotiq_finger_2_link_paramedian_hinge"/>
    <axis xyz="0 0 1"/>
    <!-- -0.37 is hand picked, 0.9719 is hand calculated from atan(0.02381/0.01625) -->
    <origin rpy="0 0 0" xyz="0 0.05715 -0.01"/>
    <limit effort="100" lower="-3.1416" upper="3.1416" velocity="100"/>
  </joint>
  <gazebo reference="robotiq_finger_2_joint_paramedian_hinge">
    <implicitSpringDamper>1</implicitSpringDamper>
  </gazebo>
  <joint name="robotiq_finger_2_joint_median_actuating_hinge_median_bar" type="revolute">
    <parent link="robotiq_finger_2_link_median_actuating_hinge"/>
    <child link="robotiq_finger_2_link_median_bar"/>
    <axis xyz="0 0 1"/>
    <!-- hand calc 90 deg + atan(0.01516/0.01625) -->
    <origin rpy="0 0 2.3215" xyz="0.01625 0.01516 0"/>
    <limit effort="100" lower="-3.1416" upper="3.1416" velocity="100"/>
  </joint>
  <gazebo reference="robotiq_finger_2_joint_median_actuating_hinge_median_bar">
    <implicitSpringDamper>1</implicitSpringDamper>
  </gazebo>
  <joint name="robotiq_finger_2_joint_paradistal_hinge" type="revolute">
    <parent link="robotiq_finger_2_link_2"/>
    <child link="robotiq_finger_2_link_paradistal_hinge"/>
    <axis xyz="0 0 1"/>
    <origin rpy="0 0 0" xyz="0 0.039 -0.01"/>
    <limit effort="100" lower="-3.1416" upper="3.1416" velocity="100"/>
  </joint>
  <gazebo reference="robotiq_finger_2_joint_paradistal_hinge">
    <implicitSpringDamper>1</implicitSpringDamper>
  </gazebo>
  <joint name="robotiq_finger_2_joint_paramedian_hinge_median_bar_underactuated" type="revolute">
    <parent link="robotiq_finger_2_link_paramedian_hinge"/>
    <child link="robotiq_finger_2_link_median_bar_underactuated"/>
    <axis xyz="0 0 1"/>
    <!-- hand calc 90 deg + atan(0.01227/0.00329) -->
    <origin rpy="0 0 1.5708" xyz="0.01227 0.00329 0"/>
    <limit effort="100" lower="-3.1416" upper="3.1416" velocity="100"/>
  </joint>
  <gazebo reference="robotiq_finger_2_joint_paramedian_hinge_median_bar_underactuated">
    <implicitSpringDamper>1</implicitSpringDamper>
  </gazebo>
  <joint name="robotiq_finger_2_joint_1" type="revolute">
    <origin rpy="0 0 -2.0906" xyz="0 0 0"/>
    <axis xyz="0 0 1"/>
    <parent link="robotiq_finger_2_link_0"/>
    <child link="robotiq_finger_2_link_1"/>
    <dynamics damping="1" friction="0"/>
    <!-- Limits: [0deg.,70deg.] -->
    <limit effort="60" lower="0" upper="1.2217" velocity="-1"/>
  </joint>
  <gazebo reference="robotiq_finger_2_joint_1">
    <implicitSpringDamper>1</implicitSpringDamper>
  </gazebo>
  <joint name="robotiq_finger_2_joint_2" type="revolute">
    <parent link="robotiq_finger_2_link_1"/>
    <child link="robotiq_finger_2_link_2"/>
    <dynamics damping="1" friction="0"/>
    <axis xyz="0 0 1"/>
    <origin rpy="0 0 0" xyz="0 0.05715 0"/>
    <!-- Limits: [0deg.,90deg.] -->
    <limit effort="60" lower="0" upper="1.5708" velocity="-1"/>
  </joint>
  <gazebo reference="robotiq_finger_2_joint_2">
    <implicitSpringDamper>1</implicitSpringDamper>
  </gazebo>
  <joint name="robotiq_finger_2_joint_3" type="revolute">
    <parent link="robotiq_finger_2_link_2"/>
    <child link="robotiq_finger_2_link_3"/>
    <dynamics damping="1" friction="0"/>
    <axis xyz="0 0 1"/>
    <origin rpy="0 0 2.0906" xyz="0 0.039 0"/>
    <!-- Limits: [-38deg.,60deg.] -->
    <limit effort="60" lower="-0.6632" upper="1.0471" velocity="-1"/>
  </joint>
  <gazebo reference="robotiq_finger_2_joint_3">
    <implicitSpringDamper>1</implicitSpringDamper>
  </gazebo>
  <gazebo>
    <joint name="robotiq_finger_2_link_proximal_actuating_bar_median_actuating_hinge_couple" type="revolute">
      <parent>robotiq_finger_2_link_median_actuating_hinge</parent>
      <child>robotiq_finger_2_link_proximal_actuating_bar</child>
      <pose>0.05398 0 0 0 0 0</pose>
      <axis>
        <dynamics>
          <damping>0</damping>
          <friction>0</friction>
        </dynamics>
        <xyz>0 0 1</xyz>
        <!-- <use_parent_model_frame>false</use_parent_model_frame> -->
      </axis>
    </joint>
  </gazebo>
  <gazebo reference="robotiq_finger_2_link_proximal_actuating_bar_median_actuating_hinge_couple">
    <implicitSpringDamper>1</implicitSpringDamper>
  </gazebo>
  <gazebo>
    <joint name="robotiq_finger_2_link_median_bar_link_3_couple" type="revolute">
      <parent>robotiq_finger_2_link_3</parent>
      <child>robotiq_finger_2_link_median_bar</child>
      <pose>0.0381 0 0 0 0 0</pose>
      <axis>
        <dynamics>
          <damping>0</damping>
          <friction>0</friction>
        </dynamics>
        <xyz>0 0 1</xyz>
        <!-- <use_parent_model_frame>false</use_parent_model_frame> -->
      </axis>
    </joint>
  </gazebo>
  <gazebo reference="robotiq_finger_2_link_median_bar_link_3_couple">
    <implicitSpringDamper>1</implicitSpringDamper>
  </gazebo>
  <gazebo>
    <joint name="robotiq_finger_2_link_paramedian_bar_paradistal_hinge_couple" type="revolute">
      <parent>robotiq_finger_2_link_paradistal_hinge</parent>
      <child>robotiq_finger_2_link_median_bar_underactuated</child>
      <pose>0.0381 0 0 0 0 0</pose>
      <axis>
        <dynamics>
          <damping>0</damping>
          <friction>0</friction>
        </dynamics>
        <xyz>0 0 1</xyz>
        <!-- <use_parent_model_frame>false</use_parent_model_frame> -->
      </axis>
    </joint>
  </gazebo>
  <gazebo reference="robotiq_finger_2_link_median_bar_link_3_couple">
    <implicitSpringDamper>1</implicitSpringDamper>
  </gazebo>
  <gazebo>
    <joint name="robotiq_finger_2_link_paradistal_hinge_link_3_couple" type="revolute">
      <parent>robotiq_finger_2_link_paradistal_hinge</parent>
      <child>robotiq_finger_2_link_3</child>
      <pose>0.0381 0 0 0 0 0</pose>
      <axis>
        <dynamics>
          <damping>0</damping>
          <friction>0</friction>
        </dynamics>
        <xyz>0 0 1</xyz>
        <!-- <use_parent_model_frame>false</use_parent_model_frame> -->
      </axis>
    </joint>
  </gazebo>
  <gazebo reference="robotiq_finger_2_link_paradistal_hinge_link_3_couple">
    <implicitSpringDamper>1</implicitSpringDamper>
  </gazebo>
  <gazebo>
    <joint name="robotiq_finger_2_link_paraproximal_bar_paramedian_hinge_couple" type="revolute">
      <parent>robotiq_finger_2_link_paramedian_hinge</parent>
      <child>robotiq_finger_2_link_paraproximal_bar</child>
      <pose>0.05770 0 0 0 0 0</pose>
      <axis>
        <dynamics>
          <damping>0</damping>
          <friction>0</friction>
        </dynamics>
        <xyz>0 0 1</xyz>
        <!-- <use_parent_model_frame>false</use_parent_model_frame> -->
      </axis>
    </joint>
  </gazebo>
  <gazebo reference="robotiq_finger_2_link_paraproximal_bar_paramedian_hinge_couple">
    <implicitSpringDamper>1</implicitSpringDamper>
  </gazebo>
  <link name="robotiq_finger_middle_link_0">
    <visual>
      <origin rpy="0 0 0" xyz="0 0 0"/>
      <geometry>
        <mesh filename="package://robotiq_s_model_visualization/meshes/s-model_articulated/visual/link_0.STL"/>
      </geometry>
      <material name="green">
        <color rgba="0 1 0 1"/>
      </material>
    </visual>
    <collision>
      <origin rpy="0 0 0" xyz="0 0 0"/>
      <geometry>
        <mesh filename="package://robotiq_s_model_visualization/meshes/s-model_articulated/collision/link_0.STL"/>
      </geometry>
      <material name="yellow">
        <color rgba="0 1 1 1"/>
      </material>
    </collision>
    <inertial>
      <mass value="0.1"/>
      <origin xyz="-0.01 0 0"/>
      <inertia ixx="0.000018" ixy="0" ixz="0" iyy="0.000025" iyz="0" izz="0.000025"/>
    </inertial>
  </link>
  <gazebo reference="robotiq_finger_middle_link_0">
    <mu1>1.1</mu1>
    <mu2>1.1</mu2>
  </gazebo>
  <link name="robotiq_finger_middle_link_1">
    <visual>
      <origin rpy="0 0 1.5708" xyz="0 0.05717 0"/>
      <geometry>
        <mesh filename="package://robotiq_s_model_visualization/meshes/s-model_articulated/visual/link_1.STL"/>
      </geometry>
      <material name="green"/>
    </visual>
    <collision>
      <origin rpy="0 0 1.5708" xyz="0 0.05717 0"/>
      <geometry>
        <mesh filename="package://robotiq_s_model_visualization/meshes/s-model_articulated/collision/link_1.STL"/>
      </geometry>
      <material name="yellow">
        <color rgba="0 1 1 1"/>
      </material>
    </collision>
    <inertial>
      <origin rpy="0 0 1.5708" xyz="0.00053 0.03218 0"/>
      <mass value="0.047"/>
      <inertia ixx="0.00000499332" ixy="0.00000091312" ixz="-0.00000000120" iyy="0.00006434531" iyz="-0.00000000007" izz="0.00006061917"/>
    </inertial>
  </link>
  <gazebo reference="robotiq_finger_middle_link_1">
    <mu1>1.1</mu1>
    <mu2>1.1</mu2>
  </gazebo>
  <link name="robotiq_finger_middle_link_2">
    <visual>
      <origin rpy="0 0 1.5708" xyz="0 0.03810 0.0075"/>
      <geometry>
        <mesh filename="package://robotiq_s_model_visualization/meshes/s-model_articulated/visual/link_2.STL"/>
      </geometry>
      <material name="green"/>
    </visual>
    <collision>
      <origin rpy="0 0 1.5708" xyz="0 0.03810 0.0075"/>
      <geometry>
        <mesh filename="package://robotiq_s_model_visualization/meshes/s-model_articulated/collision/link_2.STL"/>
      </geometry>
      <material name="yellow"/>
    </collision>
    <inertial>
      <origin rpy="0 0 1.5708" xyz="0.00048 0.02167 0.00018"/>
      <mass value="0.03284"/>
      <inertia ixx="0.00000348008" ixy="0.00000031940" ixz="0.00000013041" iyy="0.00002248123" iyz="0.00000000291" izz="0.00001986346"/>
    </inertial>
  </link>
  <gazebo reference="robotiq_finger_middle_link_2">
    <mu1>1.1</mu1>
    <mu2>1.1</mu2>
  </gazebo>
  <link name="robotiq_finger_middle_link_3">
    <visual>
      <origin rpy="0 0 0" xyz="0 0 0"/>
      <geometry>
        <mesh filename="package://robotiq_s_model_visualization/meshes/s-model_articulated/visual/link_3.STL"/>
      </geometry>
      <material name="green"/>
    </visual>
    <collision>
      <origin rpy="0 0 0" xyz="0 0 0"/>
      <geometry>
        <mesh filename="package://robotiq_s_model_visualization/meshes/s-model_articulated/collision/link_3.STL"/>
      </geometry>
      <material name="yellow"/>
    </collision>
    <inertial>
      <origin rpy="0 0 0" xyz="0.01626 0.00049 0.0002"/>
      <mass value="0.03354"/>
      <inertia ixx="0.00000305151" ixy="0.00000089792" ixz="0.00000000249" iyy="0.00001427978" iyz="-0.00000001191" izz="0.00001264126"/>
    </inertial>
  </link>
  <gazebo reference="robotiq_finger_middle_link_3">
    <mu1>1.1</mu1>
    <mu2>1.1</mu2>
  </gazebo>
  <link name="robotiq_finger_middle_link_proximal_actuating_hinge">
    <visual>
      <origin rpy="0 0 0" xyz="0.01429 0 0"/>
      <geometry>
        <box size="0.02858 .0075 .002"/>
      </geometry>
    </visual>
    <collision>
      <origin rpy="0 0 0" xyz="0.01429 0 0"/>
      <geometry>
        <box size="0.02858 .0075 .002"/>
      </geometry>
    </collision>
    <inertial>
      <origin rpy="0 0 0" xyz="0.0012 -0.00162 -0.00161"/>
      <mass value="0.02647"/>
      <inertia ixx="0.00000156447" ixy="0.000000236226" ixz="-0.00000014862" iyy="0.00000221068" iyz="-0.00000014369" izz="0.00000323175"/>
    </inertial>
  </link>
  <gazebo reference="robotiq_finger_middle_link_proximal_actuating_hinge">
    <mu1>1.1</mu1>
    <mu2>1.1</mu2>
  </gazebo>
  <link name="robotiq_finger_middle_link_paraproximal_actuating_hinge">
    <visual>
      <origin rpy="0 0 0" xyz="0.01143 0 0"/>
      <geometry>
        <box size="0.02286 .0075 .002"/>
      </geometry>
    </visual>
    <collision>
      <origin rpy="0 0 0" xyz="0.01143 0 0"/>
      <geometry>
        <box size="0.02286 .0075 .002"/>
      </geometry>
    </collision>
    <inertial>
      <origin rpy="0 0 0" xyz="0.0064 0 0"/>
      <!-- copied from proximal_actuating_hinge -->
      <mass value="0.00362"/>
      <inertia ixx="0.00000012043" ixy="0" ixz="0" iyy="0.00000053588" iyz="0" izz="0.00000065322"/>
    </inertial>
  </link>
  <gazebo reference="robotiq_finger_middle_link_paraproximal_actuating_hinge">
    <mu1>1.1</mu1>
    <mu2>1.1</mu2>
  </gazebo>
  <link name="robotiq_finger_middle_link_proximal_actuating_bar">
    <visual>
      <origin rpy="0 0 0" xyz="0.026789 0 0"/>
      <geometry>
        <box size="0.05398 .0075 .002"/>
      </geometry>
    </visual>
    <collision>
      <origin rpy="0 0 0" xyz="0.026789 0 0"/>
      <geometry>
        <box size="0.05398 .0075 .002"/>
      </geometry>
    </collision>
    <inertial>
      <origin rpy="0 0 0" xyz="0.02699 -0.00122 0"/>
      <mass value="0.00659"/>
      <inertia ixx="0.00000008348" ixy="-0.0000002179" ixz="0.00000000134" iyy="0.00000719076" iyz="0" izz="0.00000718272"/>
    </inertial>
  </link>
  <gazebo reference="robotiq_finger_middle_link_proximal_actuating_bar">
    <mu1>1.1</mu1>
    <mu2>1.1</mu2>
  </gazebo>
  <link name="robotiq_finger_middle_link_paraproximal_bar">
    <visual>
      <origin rpy="0 0 0" xyz="0.02885 0 0"/>
      <geometry>
        <box size="0.05770 .0075 .002"/>
      </geometry>
    </visual>
    <collision>
      <origin rpy="0 0 0" xyz="0.02885 0 0"/>
      <geometry>
        <box size="0.05770 .0075 .002"/>
      </geometry>
    </collision>
    <inertial>
      <origin rpy="0 0 0" xyz="0.02858 -0.00129 0"/>
      <mass value="0.00732"/>
      <inertia ixx="0.00000009065" ixy="-0.00000027047" ixz="0.00000000142" iyy="0.00000878034" iyz="0" izz="0.00000877558"/>
    </inertial>
  </link>
  <gazebo reference="robotiq_finger_middle_link_paraproximal_bar">
    <mu1>1.1</mu1>
    <mu2>1.1</mu2>
  </gazebo>
  <link name="robotiq_finger_middle_link_median_actuating_hinge">
    <visual>
      <origin rpy="0 0 0" xyz="0 0 0"/>
      <geometry>
        <box size=".02 .02 .002"/>
      </geometry>
    </visual>
    <collision>
      <origin rpy="0 0 0" xyz="0 0 0"/>
      <geometry>
        <box size=".02 .02 .002"/>
      </geometry>
    </collision>
    <inertial>
      <origin rpy="0 0 0" xyz="0.0092 0.00514 0"/>
      <mass value="0.00359"/>
      <inertia ixx="0.00000024735" ixy="0.00000023619" ixz="0" iyy="0.00000047681" iyz="0" izz="0.00000071813"/>
    </inertial>
  </link>
  <gazebo reference="robotiq_finger_middle_link_median_actuating_hinge">
    <mu1>1.1</mu1>
    <mu2>1.1</mu2>
  </gazebo>
  <link name="robotiq_finger_middle_link_median_bar">
    <visual>
      <origin rpy="0 0 0" xyz="0.01905 0 0"/>
      <geometry>
        <box size="0.0381 .0075 .002"/>
      </geometry>
    </visual>
    <collision>
      <origin rpy="0 0 0" xyz="0.01905 0 0"/>
      <geometry>
        <box size="0.0381 .0075 .002"/>
      </geometry>
    </collision>
    <inertial>
      <origin rpy="0 0 0" xyz="0.01905 -0.00107 0"/>
      <mass value="0.00538"/>
      <inertia ixx="0.00000006639" ixy="-0.00000010996" ixz="0.00000000094" iyy="0.00000305318" iyz="0" izz="0.00000304657"/>
    </inertial>
  </link>
  <gazebo reference="robotiq_finger_middle_link_median_bar">
    <mu1>1.1</mu1>
    <mu2>1.1</mu2>
  </gazebo>
  <link name="robotiq_finger_middle_link_paramedian_hinge">
    <visual>
      <origin rpy="0 0 0" xyz="0 0 0"/>
      <geometry>
        <box size=".02 .02 .002"/>
      </geometry>
    </visual>
    <collision>
      <origin rpy="0 0 0" xyz="0 0 0"/>
      <geometry>
        <box size=".02 .02 .002"/>
      </geometry>
    </collision>
    <inertial>
      <origin rpy="0 0 0" xyz="-0.01025 0.00046 0"/>
      <mass value="0.00276"/>
      <inertia ixx="0.00000004213" ixy="-0.00000001491" ixz="0" iyy="0.00000050258" iyz="0" izz="0.00000054007"/>
    </inertial>
  </link>
  <gazebo reference="robotiq_finger_middle_link_paramedian_hinge">
    <mu1>1.1</mu1>
    <mu2>1.1</mu2>
  </gazebo>
  <link name="robotiq_finger_middle_link_median_bar_underactuated">
    <visual>
      <origin rpy="0 0 0" xyz="0.01905 0 0"/>
      <geometry>
        <box size="0.0381 .0075 .002"/>
      </geometry>
    </visual>
    <collision>
      <origin rpy="0 0 0" xyz="0.01905 0 0"/>
      <geometry>
        <box size="0.0381 .0075 .002"/>
      </geometry>
    </collision>
    <inertial>
      <origin rpy="0 0 0" xyz="0.01905 -0.00107 0"/>
      <mass value="0.00538"/>
      <inertia ixx="0.00000006639" ixy="-0.00000010996" ixz="-0.00000000094" iyy="0.00000305318" iyz="0" izz="0.00000304657"/>
    </inertial>
  </link>
  <gazebo reference="robotiq_finger_middle_link_median_bar_underactuated">
    <mu1>1.1</mu1>
    <mu2>1.1</mu2>
  </gazebo>
  <link name="robotiq_finger_middle_link_paradistal_hinge">
    <visual>
      <origin rpy="0 0 0" xyz="0 0 0"/>
      <geometry>
        <box size=".02 .02 .002"/>
      </geometry>
    </visual>
    <collision>
      <origin rpy="0 0 0" xyz="0 0 0"/>
      <geometry>
        <box size=".02 0.02 .002"/>
      </geometry>
    </collision>
    <inertial>
      <origin rpy="0 0 0" xyz="0.00548 0 0"/>
      <mass value="0.00158"/>
      <inertia ixx="0.00000001907" ixy="0" ixz="0" iyy="0.00000010970" iyz="0" izz="0.00000012610"/>
    </inertial>
  </link>
  <gazebo reference="robotiq_finger_middle_link_paradistal_hinge">
    <mu1>1.1</mu1>
    <mu2>1.1</mu2>
  </gazebo>
  <joint name="robotiq_finger_middle_joint_proximal_actuating_hinge" type="revolute">
    <parent link="robotiq_finger_middle_link_0"/>
    <child link="robotiq_finger_middle_link_proximal_actuating_hinge"/>
    <axis xyz="0 0 1"/>
    <origin rpy="0 0 -2.0906" xyz="0 0 0.01"/>
    <limit effort="100" lower="-3.1416" upper="3.1416" velocity="100"/>
  </joint>
  <gazebo reference="robotiq_finger_middle_joint_proximal_actuating_hinge">
    <implicitSpringDamper>1</implicitSpringDamper>
  </gazebo>
  <joint name="robotiq_finger_middle_joint_paraproximal_actuating_hinge" type="revolute">
    <parent link="robotiq_finger_middle_link_0"/>
    <child link="robotiq_finger_middle_link_paraproximal_actuating_hinge"/>
    <axis xyz="0 0 1"/>
    <origin rpy="0 0 -2.0906" xyz="0 0 -0.01"/>
    <limit effort="100" lower="-3.1416" upper="3.1416" velocity="100"/>
  </joint>
  <gazebo reference="robotiq_finger_middle_joint_paraproximal_actuating_hinge">
    <implicitSpringDamper>1</implicitSpringDamper>
  </gazebo>
  <joint name="robotiq_finger_middle_joint_proximal_actuating_bar" type="revolute">
    <parent link="robotiq_finger_middle_link_proximal_actuating_hinge"/>
    <child link="robotiq_finger_middle_link_proximal_actuating_bar"/>
    <axis xyz="0 0 1"/>
    <origin rpy="0 0 1.8616" xyz="0.02858 0 0"/>
    <limit effort="100" lower="-3.1416" upper="3.1416" velocity="100"/>
  </joint>
  <gazebo reference="robotiq_finger_middle_joint_proximal_actuating_bar">
    <implicitSpringDamper>1</implicitSpringDamper>
  </gazebo>
  <joint name="robotiq_finger_middle_joint_paraproximal_bar" type="revolute">
    <parent link="robotiq_finger_middle_link_paraproximal_actuating_hinge"/>
    <child link="robotiq_finger_middle_link_paraproximal_bar"/>
    <axis xyz="0 0 1"/>
    <origin rpy="0 0 1.57" xyz="0.02286 0 0"/>
    <limit effort="100" lower="-3.1416" upper="3.1416" velocity="100"/>
  </joint>
  <gazebo reference="robotiq_finger_middle_joint_paraproximal_bar">
    <implicitSpringDamper>1</implicitSpringDamper>
  </gazebo>
  <joint name="robotiq_finger_middle_joint_median_actuating_hinge" type="revolute">
    <parent link="robotiq_finger_middle_link_1"/>
    <child link="robotiq_finger_middle_link_median_actuating_hinge"/>
    <axis xyz="0 0 1"/>
    <origin rpy="0 0 -0.37" xyz="0 0.05715 0.01"/>
    <limit effort="100" lower="-3.1416" upper="3.1416" velocity="100"/>
  </joint>
  <gazebo reference="robotiq_finger_middle_joint_median_actuating_hinge">
    <implicitSpringDamper>1</implicitSpringDamper>
  </gazebo>
  <joint name="robotiq_finger_middle_joint_paramedian_hinge" type="revolute">
    <parent link="robotiq_finger_middle_link_1"/>
    <child link="robotiq_finger_middle_link_paramedian_hinge"/>
    <axis xyz="0 0 1"/>
    <!-- -0.37 is hand picked, 0.9719 is hand calculated from atan(0.02381/0.01625) -->
    <origin rpy="0 0 0" xyz="0 0.05715 -0.01"/>
    <limit effort="100" lower="-3.1416" upper="3.1416" velocity="100"/>
  </joint>
  <gazebo reference="robotiq_finger_middle_joint_paramedian_hinge">
    <implicitSpringDamper>1</implicitSpringDamper>
  </gazebo>
  <joint name="robotiq_finger_middle_joint_median_actuating_hinge_median_bar" type="revolute">
    <parent link="robotiq_finger_middle_link_median_actuating_hinge"/>
    <child link="robotiq_finger_middle_link_median_bar"/>
    <axis xyz="0 0 1"/>
    <!-- hand calc 90 deg + atan(0.01516/0.01625) -->
    <origin rpy="0 0 2.3215" xyz="0.01625 0.01516 0"/>
    <limit effort="100" lower="-3.1416" upper="3.1416" velocity="100"/>
  </joint>
  <gazebo reference="robotiq_finger_middle_joint_median_actuating_hinge_median_bar">
    <implicitSpringDamper>1</implicitSpringDamper>
  </gazebo>
  <joint name="robotiq_finger_middle_joint_paradistal_hinge" type="revolute">
    <parent link="robotiq_finger_middle_link_2"/>
    <child link="robotiq_finger_middle_link_paradistal_hinge"/>
    <axis xyz="0 0 1"/>
    <origin rpy="0 0 0" xyz="0 0.039 -0.01"/>
    <limit effort="100" lower="-3.1416" upper="3.1416" velocity="100"/>
  </joint>
  <gazebo reference="robotiq_finger_middle_joint_paradistal_hinge">
    <implicitSpringDamper>1</implicitSpringDamper>
  </gazebo>
  <joint name="robotiq_finger_middle_joint_paramedian_hinge_median_bar_underactuated" type="revolute">
    <parent link="robotiq_finger_middle_link_paramedian_hinge"/>
    <child link="robotiq_finger_middle_link_median_bar_underactuated"/>
    <axis xyz="0 0 1"/>
    <!-- hand calc 90 deg + atan(0.01227/0.00329) -->
    <origin rpy="0 0 1.5708" xyz="0.01227 0.00329 0"/>
    <limit effort="100" lower="-3.1416" upper="3.1416" velocity="100"/>
  </joint>
  <gazebo reference="robotiq_finger_middle_joint_paramedian_hinge_median_bar_underactuated">
    <implicitSpringDamper>1</implicitSpringDamper>
  </gazebo>
  <joint name="robotiq_finger_middle_joint_1" type="revolute">
    <origin rpy="0 0 -2.0906" xyz="0 0 0"/>
    <axis xyz="0 0 1"/>
    <parent link="robotiq_finger_middle_link_0"/>
    <child link="robotiq_finger_middle_link_1"/>
    <dynamics damping="1" friction="0"/>
    <!-- Limits: [0deg.,70deg.] -->
    <limit effort="60" lower="0" upper="1.2217" velocity="-1"/>
  </joint>
  <gazebo reference="robotiq_finger_middle_joint_1">
    <implicitSpringDamper>1</implicitSpringDamper>
  </gazebo>
  <joint name="robotiq_finger_middle_joint_2" type="revolute">
    <parent link="robotiq_finger_middle_link_1"/>
    <child link="robotiq_finger_middle_link_2"/>
    <dynamics damping="1" friction="0"/>
    <axis xyz="0 0 1"/>
    <origin rpy="0 0 0" xyz="0 0.05715 0"/>
    <!-- Limits: [0deg.,90deg.] -->
    <limit effort="60" lower="0" upper="1.5708" velocity="-1"/>
  </joint>
  <gazebo reference="robotiq_finger_middle_joint_2">
    <implicitSpringDamper>1</implicitSpringDamper>
  </gazebo>
  <joint name="robotiq_finger_middle_joint_3" type="revolute">
    <parent link="robotiq_finger_middle_link_2"/>
    <child link="robotiq_finger_middle_link_3"/>
    <dynamics damping="1" friction="0"/>
    <axis xyz="0 0 1"/>
    <origin rpy="0 0 2.0906" xyz="0 0.039 0"/>
    <!-- Limits: [-38deg.,60deg.] -->
    <limit effort="60" lower="-0.6632" upper="1.0471" velocity="-1"/>
  </joint>
  <gazebo reference="robotiq_finger_middle_joint_3">
    <implicitSpringDamper>1</implicitSpringDamper>
  </gazebo>
  <gazebo>
    <joint name="robotiq_finger_middle_link_proximal_actuating_bar_median_actuating_hinge_couple" type="revolute">
      <parent>robotiq_finger_middle_link_median_actuating_hinge</parent>
      <child>robotiq_finger_middle_link_proximal_actuating_bar</child>
      <pose>0.05398 0 0 0 0 0</pose>
      <axis>
        <dynamics>
          <damping>0</damping>
          <friction>0</friction>
        </dynamics>
        <xyz>0 0 1</xyz>
        <!-- <use_parent_model_frame>false</use_parent_model_frame> -->
      </axis>
    </joint>
  </gazebo>
  <gazebo reference="robotiq_finger_middle_link_proximal_actuating_bar_median_actuating_hinge_couple">
    <implicitSpringDamper>1</implicitSpringDamper>
  </gazebo>
  <gazebo>
    <joint name="robotiq_finger_middle_link_median_bar_link_3_couple" type="revolute">
      <parent>robotiq_finger_middle_link_3</parent>
      <child>robotiq_finger_middle_link_median_bar</child>
      <pose>0.0381 0 0 0 0 0</pose>
      <axis>
        <dynamics>
          <damping>0</damping>
          <friction>0</friction>
        </dynamics>
        <xyz>0 0 1</xyz>
        <!-- <use_parent_model_frame>false</use_parent_model_frame> -->
      </axis>
    </joint>
  </gazebo>
  <gazebo reference="robotiq_finger_middle_link_median_bar_link_3_couple">
    <implicitSpringDamper>1</implicitSpringDamper>
  </gazebo>
  <gazebo>
    <joint name="robotiq_finger_middle_link_paramedian_bar_paradistal_hinge_couple" type="revolute">
      <parent>robotiq_finger_middle_link_paradistal_hinge</parent>
      <child>robotiq_finger_middle_link_median_bar_underactuated</child>
      <pose>0.0381 0 0 0 0 0</pose>
      <axis>
        <dynamics>
          <damping>0</damping>
          <friction>0</friction>
        </dynamics>
        <xyz>0 0 1</xyz>
        <!-- <use_parent_model_frame>false</use_parent_model_frame> -->
      </axis>
    </joint>
  </gazebo>
  <gazebo reference="robotiq_finger_middle_link_median_bar_link_3_couple">
    <implicitSpringDamper>1</implicitSpringDamper>
  </gazebo>
  <gazebo>
    <joint name="robotiq_finger_middle_link_paradistal_hinge_link_3_couple" type="revolute">
      <parent>robotiq_finger_middle_link_paradistal_hinge</parent>
      <child>robotiq_finger_middle_link_3</child>
      <pose>0.0381 0 0 0 0 0</pose>
      <axis>
        <dynamics>
          <damping>0</damping>
          <friction>0</friction>
        </dynamics>
        <xyz>0 0 1</xyz>
        <!-- <use_parent_model_frame>false</use_parent_model_frame> -->
      </axis>
    </joint>
  </gazebo>
  <gazebo reference="robotiq_finger_middle_link_paradistal_hinge_link_3_couple">
    <implicitSpringDamper>1</implicitSpringDamper>
  </gazebo>
  <gazebo>
    <joint name="robotiq_finger_middle_link_paraproximal_bar_paramedian_hinge_couple" type="revolute">
      <parent>robotiq_finger_middle_link_paramedian_hinge</parent>
      <child>robotiq_finger_middle_link_paraproximal_bar</child>
      <pose>0.05770 0 0 0 0 0</pose>
      <axis>
        <dynamics>
          <damping>0</damping>
          <friction>0</friction>
        </dynamics>
        <xyz>0 0 1</xyz>
        <!-- <use_parent_model_frame>false</use_parent_model_frame> -->
      </axis>
    </joint>
  </gazebo>
  <gazebo reference="robotiq_finger_middle_link_paraproximal_bar_paramedian_hinge_couple">
    <implicitSpringDamper>1</implicitSpringDamper>
  </gazebo>
  <link name="robotiq_palm">
    <visual>
      <geometry>
        <mesh filename="package://robotiq_s_model_visualization/meshes/s-model_articulated/visual/palm.STL"/>
      </geometry>
      <material name="green">
        <color rgba="0 1 0 1"/>
      </material>
    </visual>
    <!-- Simple shape collision -->
    <collision>
      <origin rpy="0 0 0" xyz="0 0 0"/>
      <geometry>
        <box size="0.1 0.1 0.1"/>
      </geometry>
      <material name="yellow">
        <color rgba="0 1 1 1"/>
      </material>
    </collision>
    <inertial>
      <origin rpy="0 0 0" xyz="0 0 0"/>
      <mass value="1.3"/>
      <inertia ixx="0.0035" ixy="0" ixz="-0" iyy="0.0035" iyz="0" izz="0.0035"/>
    </inertial>
  </link>
  <gazebo reference="robotiq_palm">
    <mu1>1.1</mu1>
    <mu2>1.1</mu2>
  </gazebo>
  <joint name="robotiq_palm_finger_1_joint" type="revolute">
    <parent link="robotiq_palm"/>
    <child link="robotiq_finger_1_link_0"/>
    <dynamics damping="1" friction="0"/>
    <axis xyz="0 1 0"/>
    <origin rpy="0 3.1416 -1.57" xyz="-0.0455 0.0214 0.036"/>
    <!-- Limits: [-17deg.,17deg.] -->
    <limit effort="60" lower="-0.2967" upper="0.2967" velocity="-1"/>
  </joint>
  <gazebo reference="robotiq_palm_finger_1_joint">
    <implicitSpringDamper>1</implicitSpringDamper>
  </gazebo>
  <joint name="robotiq_palm_finger_2_joint" type="revolute">
    <parent link="robotiq_palm"/>
    <child link="robotiq_finger_2_link_0"/>
    <dynamics damping="1" friction="0"/>
    <axis xyz="0 1 0"/>
    <origin rpy="0 3.1416 -1.57" xyz="-0.0455 0.0214 -0.036"/>
    <!-- Limits: [-17deg.,17deg.] -->
    <limit effort="60" lower="-0.2967" upper="0.2967" velocity="-1"/>
  </joint>
  <gazebo reference="robotiq_palm_finger_2_joint">
    <implicitSpringDamper>1</implicitSpringDamper>
  </gazebo>
  <joint name="robotiq_palm_finger_middle_joint" type="revolute">
    <parent link="robotiq_palm"/>
    <child link="robotiq_finger_middle_link_0"/>
    <dynamics damping="1" friction="0"/>
    <axis xyz="0 1 0"/>
    <origin rpy="0 0 1.57" xyz="0.0455 0.0214 0"/>
    <limit effort="60" lower="0" upper="0" velocity="-1"/>
  </joint>
  <gazebo reference="robotiq_palm_finger_middle_joint">
    <implicitSpringDamper>1</implicitSpringDamper>
  </gazebo>
</robot>

